Workbook

Sheet Profit and Loss Statement
E1: BORROWER_NAME
E2: BORROWER_CODE
A3: 8e28cb47-8f2a-4284-a118-9bff91643dd9 | E3: TEMPLATE_NAME | F3: Company Financial Template
E4: PROJECT_NAME
E5: ACCOUNTING_TYPE | F5: GAAP
E6: FINANCIAL_TYPE | F6: Consolidated
E7: YEAR | F7: =IF(F9="","",YEAR(F9)) | G7: =IF(G9="","",YEAR(G9)) | H7: =IF(H9="","",YEAR(H9)) | I7: =IF(I9="","",YEAR(I9)) | J7: =IF(J9="","",YEAR(J9)) | K7: =IF(K9="","",YEAR(K9)) | L7: =IF(L9="","",YEAR(L9)) | M7: =IF(M9="","",YEAR(M9)) | ... AI7: =IF(AI9="","",YEAR(AI9))
E8: YEAR_TYPE | F8: Audited
E9: STATEMENT_DATE (YYYY-MM-DD)
E10: NO_OF_MONTHS
E11: CURRENCY | F11: INR | G11: =F11 -> INR | H11: =G11 -> INR | I11: =H11 -> INR | J11: =I11 -> INR | K11: =J11 -> INR | L11: =K11 -> INR | M11: =L11 -> INR | N11: =M11 -> INR | ... AI11: =AH11 -> INR
E12: DENOMINATION | F12: Crores | G12: =F12 -> Crores | H12: =G12 -> Crores | I12: =H12 -> Crores | J12: =I12 -> Crores | K12: =J12 -> Crores | L12: =K12 -> Crores | M12: =L12 -> Crores | N12: =M12 -> Crores | ... AI12: =AH12 -> Crores
E13: AUDITOR_NAME
E14: VERSION
E15: CIF_ID
E16: BASE_YEAR
F17: 1 | G17: 2 | H17: 3 | I17: 4 | J17: 5 | K17: 6 | L17: 7 | M17: 8 | N17: 9 | O17: 10 | P17: 11 | Q17: 12 | R17: 13 | S17: 14 | T17: 15 | U17: 16 | V17: 17 | W17: 18 | X17: 19 | Y17: 20 | Z17: 21 | AA17: 22 | AB17: 23 | AC17: 24 | AD17: 25 | AE17: 26 | AF17: 27 | AG17: 28 | AH17: 29 | AI17: 30
A18: UUID | B18: PARENT ID | C18: AUTO_SEQUENCE | D18: INPUT_SEQUENCE | E18: LINE_ITEM_NAME | F18: VALUE | G18: VALUE | H18: VALUE | I18: VALUE | J18: VALUE | K18: VALUE | L18: VALUE | M18: VALUE | N18: VALUE | O18: VALUE | P18: VALUE | Q18: VALUE | R18: VALUE | S18: VALUE | T18: VALUE | U18: VALUE | V18: VALUE | W18: VALUE | X18: VALUE | Y18: VALUE | Z18: VALUE | AA18: VALUE | AB18: VALUE | AC18: VALUE | AD18: VALUE | AE18: VALUE | AF18: VALUE | AG18: VALUE | AH18: VALUE | AI18: VALUE
A19: c98dd930-c06b-4184-a258-ac39cd19a193 | C19: 1 | E19: Profit and Loss Statement
A20: 10a60949-9659-4ea4-b1c3-1f16074a2874 | B20: c98dd930-c06b-4184-a258-ac39cd19a193 | C20: 1.1 | D20: 1 | E20: Gross Sales
A21: 1fe0fddb-2578-4028-bb64-bd63d70cdd09 | B21: 10a60949-9659-4ea4-b1c3-1f16074a2874 | C21: 1.1.1 | D21: 1.1 | E21: Domestic Sales
A22: 725d10e1-e2a6-4996-b9d0-4ad6ffc75b68 | B22: 10a60949-9659-4ea4-b1c3-1f16074a2874 | C22: 1.1.2 | D22: 1.2 | E22: Export Sales
A23: 640dbfc9-deeb-44e3-9198-96949e0cae58 | B23: 10a60949-9659-4ea4-b1c3-1f16074a2874 | C23: 1.1.3 | D23: 1.3 | E23: Total | F23: =ROUND(SUM(F$21:F$22),2) -> 0 | G23: =ROUND(SUM(G$21:G$22),2) -> 0 | H23: =ROUND(SUM(H$21:H$22),2) -> 0 | I23: =ROUND(SUM(I$21:I$22),2) -> 0 | J23: =ROUND(SUM(J$21:J$22),2) -> 0 | K23: =ROUND(SUM(K$21:K$22),2) -> 0 | L23: =ROUND(SUM(L$21:L$22),2) -> 0 | M23: =ROUND(SUM(M$21:M$22),2) -> 0 | ... AI23: =ROUND(SUM(AI$21:AI$22),2) -> 0
A24: 59b1facc-2b05-4ef0-bd3c-52d6156b19af | B24: c98dd930-c06b-4184-a258-ac39cd19a193 | C24: 1.2 | D24: 2 | E24: Less Excise Duty
A25: a3c6e8f3-99c4-41a0-adec-acb5ff2f3b00 | B25: c98dd930-c06b-4184-a258-ac39cd19a193 | C25: 1.3 | D25: 3 | E25: Net Sales (1 - 2) | F25: =ROUND(F23-F24,2) -> 0 | G25: =ROUND(G23-G24,2) -> 0 | H25: =ROUND(H23-H24,2) -> 0 | I25: =ROUND(I23-I24,2) -> 0 | J25: =ROUND(J23-J24,2) -> 0 | K25: =ROUND(K23-K24,2) -> 0 | L25: =ROUND(L23-L24,2) -> 0 | M25: =ROUND(M23-M24,2) -> 0 | ... AI25: =ROUND(AI23-AI24,2) -> 0
A26: 48b561dd-2f32-4bf9-9890-f458e178e892 | B26: c98dd930-c06b-4184-a258-ac39cd19a193 | C26: 1.4 | E26: % age rise (+) or fall (-) in net sales as compared to previous year (annualised) | G26: =IF(F25=0,0,IF(G25=0,0,((G25/G10)-(F25/F10))/(F25/F10))*100) -> 0 | H26: =IF(G25=0,0,IF(H25=0,0,((H25/H10)-(G25/G10))/(G25/G10))*100) -> 0 | I26: =IF(H25=0,0,IF(I25=0,0,((I25/I10)-(H25/H10))/(H25/H10))*100) -> 0 | J26: =IF(I25=0,0,IF(J25=0,0,((J25/J10)-(I25/I10))/(I25/I10))*100) -> 0 | K26: =IF(J25=0,0,IF(K25=0,0,((K25/K10)-(J25/J10))/(J25/J10))*100) -> 0 | L26: =IF(K25=0,0,IF(L25=0,0,((L25/L10)-(K25/K10))/(K25/K10))*100) -> 0 | M26: =IF(L25=0,0,IF(M25=0,0,((M25/M10)-(L25/L10))/(L25/L10))*100) -> 0 | N26: =IF(M25=0,0,IF(N25=0,0,((N25/N10)-(M25/M10))/(M25/M10))*100) -> 0 | ... AI26: =IF(AH25=0,0,IF(AI25=0,0,((AI25/AI10)-(AH25/AH10))/(AH25/AH10))*100) -> 0
A27: 16c1b0ac-ba37-4ed6-bb75-c0d4993e9ae8 | B27: c98dd930-c06b-4184-a258-ac39cd19a193 | C27: 1.5 | E27: Other recurring income incidental to main business
A28: 758d688a-abd2-4efa-bace-54c0f837efaa | B28: c98dd930-c06b-4184-a258-ac39cd19a193 | C28: 1.6 | D28: 4 | E28: Total operating income | F28: =F25+F27 -> 0 | G28: =G25+G27 -> 0 | H28: =H25+H27 -> 0 | I28: =I25+I27 -> 0 | J28: =J25+J27 -> 0 | K28: =K25+K27 -> 0 | L28: =L25+L27 -> 0 | M28: =M25+M27 -> 0 | ... AI28: =AI25+AI27 -> 0
A29: 03e7d409-963e-4698-9508-323cb4718bd7 | B29: c98dd930-c06b-4184-a258-ac39cd19a193 | C29: 1.7 | D29: 5 | E29: Cost of Sales
A30: 3d4377af-5b9d-4fc5-8ad3-56f2be931ed3 | B30: 03e7d409-963e-4698-9508-323cb4718bd7 | C30: 1.7.1 | D30: i. | E30: Raw materials | F30: =ROUND(SUM(F$31:F$32),2) -> 0 | G30: =ROUND(SUM(G$31:G$32),2) -> 0 | H30: =ROUND(SUM(H$31:H$32),2) -> 0 | I30: =ROUND(SUM(I$31:I$32),2) -> 0 | J30: =ROUND(SUM(J$31:J$32),2) -> 0 | K30: =ROUND(SUM(K$31:K$32),2) -> 0 | L30: =ROUND(SUM(L$31:L$32),2) -> 0 | M30: =ROUND(SUM(M$31:M$32),2) -> 0 | ... AI30: =ROUND(SUM(AI$31:AI$32),2) -> 0
A31: d4fd265c-aebb-4d35-8d34-fbb90f8879b1 | B31: 3d4377af-5b9d-4fc5-8ad3-56f2be931ed3 | C31: 1.7.1.1 | D31: a. | E31: i) Imported
A32: 196afb1b-3271-4e26-8c17-a1687f1442a1 | B32: 3d4377af-5b9d-4fc5-8ad3-56f2be931ed3 | C32: 1.7.1.2 | D32: b. | E32: ii) Indigenous
A33: b5374b98-fbc9-4afd-91a6-687949a4353a | B33: 03e7d409-963e-4698-9508-323cb4718bd7 | C33: 1.7.2 | D33: ii. | E33: Other Spares
A34: f78f861b-e42f-4c79-b4df-5106e411ae92 | B34: 03e7d409-963e-4698-9508-323cb4718bd7 | C34: 1.7.3 | D34: iii. | E34: Power and Fuel
A35: 148302c9-c702-4281-9fb6-424bb1a09513 | B35: 03e7d409-963e-4698-9508-323cb4718bd7 | C35: 1.7.4 | D35: iv. | E35: Direct Labour (Factory wages & salaries)
A36: a8cd1b47-c726-4920-a36e-c957dd5e4e35 | B36: 03e7d409-963e-4698-9508-323cb4718bd7 | C36: 1.7.5 | D36: v. | E36: Other manufacturing expenses | F36: =ROUND(SUM(F$37:F$39),2) -> 0 | G36: =ROUND(SUM(G$37:G$39),2) -> 0 | H36: =ROUND(SUM(H$37:H$39),2) -> 0 | I36: =ROUND(SUM(I$37:I$39),2) -> 0 | J36: =ROUND(SUM(J$37:J$39),2) -> 0 | K36: =ROUND(SUM(K$37:K$39),2) -> 0 | L36: =ROUND(SUM(L$37:L$39),2) -> 0 | M36: =ROUND(SUM(M$37:M$39),2) -> 0 | ... AI36: =ROUND(SUM(AI$37:AI$39),2) -> 0
A37: 668ded41-a4aa-46a3-9c6a-800d00837629 | B37: a8cd1b47-c726-4920-a36e-c957dd5e4e35 | C37: 1.7.5.1 | D37: a. | E37: Processing / Job Work Charges
A38: 0ad52017-0aff-4518-ab1c-4f3090d51d34 | B38: a8cd1b47-c726-4920-a36e-c957dd5e4e35 | C38: 1.7.5.2 | D38: b. | E38: Freight and Transportation Charges
A39: 4920a1ca-7f77-41b8-b737-00b8b1672a4b | B39: a8cd1b47-c726-4920-a36e-c957dd5e4e35 | C39: 1.7.5.3 | D39: c. | E39: Others
A40: 0fe0bf01-2780-473f-9a02-0a0192c5ff6c | B40: 03e7d409-963e-4698-9508-323cb4718bd7 | C40: 1.7.6 | D40: vi a. | E40: Depreciation
...

Sheet Balance Sheet
E1: BORROWER_NAME | F1: =IF('Profit and Loss Statement'!F1="","",'Profit and Loss Statement'!F1)
E2: BORROWER_CODE | F2: =IF('Profit and Loss Statement'!F2="","",'Profit and Loss Statement'!F2)
A3: e99040d4-d820-4ef1-ab86-5cb00d496a30 | E3: TEMPLATE_NAME | F3: Company Financial Template
E4: PROJECT_NAME
E5: ACCOUNTING_TYPE | F5: =IF('Profit and Loss Statement'!F5="","",'Profit and Loss Statement'!F5) -> GAAP | G5: =IF('Profit and Loss Statement'!G5="","",'Profit and Loss Statement'!G5) | H5: =IF('Profit and Loss Statement'!H5="","",'Profit and Loss Statement'!H5) | I5: =IF('Profit and Loss Statement'!I5="","",'Profit and Loss Statement'!I5) | J5: =IF('Profit and Loss Statement'!J5="","",'Profit and Loss Statement'!J5) | K5: =IF('Profit and Loss Statement'!K5="","",'Profit and Loss Statement'!K5) | L5: =IF('Profit and Loss Statement'!L5="","",'Profit and Loss Statement'!L5) | M5: =IF('Profit and Loss Statement'!M5="","",'Profit and Loss Statement'!M5) | ... AI5: =IF('Profit and Loss Statement'!AI5="","",'Profit and Loss Statement'!AI5)
E6: FINANCIAL_TYPE | F6: =IF('Profit and Loss Statement'!F6="","",'Profit and Loss Statement'!F6) -> Consolidated | G6: =IF('Profit and Loss Statement'!G6="","",'Profit and Loss Statement'!G6) | H6: =IF('Profit and Loss Statement'!H6="","",'Profit and Loss Statement'!H6) | I6: =IF('Profit and Loss Statement'!I6="","",'Profit and Loss Statement'!I6) | J6: =IF('Profit and Loss Statement'!J6="","",'Profit and Loss Statement'!J6) | K6: =IF('Profit and Loss Statement'!K6="","",'Profit and Loss Statement'!K6) | L6: =IF('Profit and Loss Statement'!L6="","",'Profit and Loss Statement'!L6) | M6: =IF('Profit and Loss Statement'!M6="","",'Profit and Loss Statement'!M6) | ... AI6: =IF('Profit and Loss Statement'!AI6="","",'Profit and Loss Statement'!AI6)
E7: YEAR | F7: =IF('Profit and Loss Statement'!F7="","",'Profit and Loss Statement'!F7) | G7: =IF('Profit and Loss Statement'!G7="","",'Profit and Loss Statement'!G7) | H7: =IF('Profit and Loss Statement'!H7="","",'Profit and Loss Statement'!H7) | I7: =IF('Profit and Loss Statement'!I7="","",'Profit and Loss Statement'!I7) | J7: =IF('Profit and Loss Statement'!J7="","",'Profit and Loss Statement'!J7) | K7: =IF('Profit and Loss Statement'!K7="","",'Profit and Loss Statement'!K7) | L7: =IF('Profit and Loss Statement'!L7="","",'Profit and Loss Statement'!L7) | M7: =IF('Profit and Loss Statement'!M7="","",'Profit and Loss Statement'!M7) | ... AI7: =IF('Profit and Loss Statement'!AI7="","",'Profit and Loss Statement'!AI7)
E8: YEAR_TYPE | F8: =IF('Profit and Loss Statement'!F8="","",'Profit and Loss Statement'!F8) -> Audited | G8: =IF('Profit and Loss Statement'!G8="","",'Profit and Loss Statement'!G8) | H8: =IF('Profit and Loss Statement'!H8="","",'Profit and Loss Statement'!H8) | I8: =IF('Profit and Loss Statement'!I8="","",'Profit and Loss Statement'!I8) | J8: =IF('Profit and Loss Statement'!J8="","",'Profit and Loss Statement'!J8) | K8: =IF('Profit and Loss Statement'!K8="","",'Profit and Loss Statement'!K8) | L8: =IF('Profit and Loss Statement'!L8="","",'Profit and Loss Statement'!L8) | M8: =IF('Profit and Loss Statement'!M8="","",'Profit and Loss Statement'!M8) | ... AI8: =IF('Profit and Loss Statement'!AI8="","",'Profit and Loss Statement'!AI8)
E9: STATEMENT_DATE (YYYY-MM-DD) | F9: =IF('Profit and Loss Statement'!F9="","",'Profit and Loss Statement'!F9) | G9: =IF('Profit and Loss Statement'!G9="","",'Profit and Loss Statement'!G9) | H9: =IF('Profit and Loss Statement'!H9="","",'Profit and Loss Statement'!H9) | I9: =IF('Profit and Loss Statement'!I9="","",'Profit and Loss Statement'!I9) | J9: =IF('Profit and Loss Statement'!J9="","",'Profit and Loss Statement'!J9) | K9: =IF('Profit and Loss Statement'!K9="","",'Profit and Loss Statement'!K9) | L9: =IF('Profit and Loss Statement'!L9="","",'Profit and Loss Statement'!L9) | M9: =IF('Profit and Loss Statement'!M9="","",'Profit and Loss Statement'!M9) | ... AI9: =IF('Profit and Loss Statement'!AI9="","",'Profit and Loss Statement'!AI9)
E10: NO_OF_MONTHS | F10: =IF('Profit and Loss Statement'!F10="","",'Profit and Loss Statement'!F10) | G10: =IF('Profit and Loss Statement'!G10="","",'Profit and Loss Statement'!G10) | H10: =IF('Profit and Loss Statement'!H10="","",'Profit and Loss Statement'!H10) | I10: =IF('Profit and Loss Statement'!I10="","",'Profit and Loss Statement'!I10) | J10: =IF('Profit and Loss Statement'!J10="","",'Profit and Loss Statement'!J10) | K10: =IF('Profit and Loss Statement'!K10="","",'Profit and Loss Statement'!K10) | L10: =IF('Profit and Loss Statement'!L10="","",'Profit and Loss Statement'!L10) | M10: =IF('Profit and Loss Statement'!M10="","",'Profit and Loss Statement'!M10) | ... AI10: =IF('Profit and Loss Statement'!AI10="","",'Profit and Loss Statement'!AI10)
E11: CURRENCY | F11: =IF('Profit and Loss Statement'!F11="","",'Profit and Loss Statement'!F11) -> INR | G11: =IF('Profit and Loss Statement'!G11="","",'Profit and Loss Statement'!G11) -> INR | H11: =IF('Profit and Loss Statement'!H11="","",'Profit and Loss Statement'!H11) -> INR | I11: =IF('Profit and Loss Statement'!I11="","",'Profit and Loss Statement'!I11) -> INR | J11: =IF('Profit and Loss Statement'!J11="","",'Profit and Loss Statement'!J11) -> INR | K11: =IF('Profit and Loss Statement'!K11="","",'Profit and Loss Statement'!K11) -> INR | L11: =IF('Profit and Loss Statement'!L11="","",'Profit and Loss Statement'!L11) -> INR | M11: =IF('Profit and Loss Statement'!M11="","",'Profit and Loss Statement'!M11) -> INR | ... AI11: =IF('Profit and Loss Statement'!AI11="","",'Profit and Loss Statement'!AI11) -> INR
E12: DENOMINATION | F12: =IF('Profit and Loss Statement'!F12="","",'Profit and Loss Statement'!F12) -> Crores | G12: =IF('Profit and Loss Statement'!G12="","",'Profit and Loss Statement'!G12) -> Crores | H12: =IF('Profit and Loss Statement'!H12="","",'Profit and Loss Statement'!H12) -> Crores | I12: =IF('Profit and Loss Statement'!I12="","",'Profit and Loss Statement'!I12) -> Crores | J12: =IF('Profit and Loss Statement'!J12="","",'Profit and Loss Statement'!J12) -> Crores | K12: =IF('Profit and Loss Statement'!K12="","",'Profit and Loss Statement'!K12) -> Crores | L12: =IF('Profit and Loss Statement'!L12="","",'Profit and Loss Statement'!L12) -> Crores | M12: =IF('Profit and Loss Statement'!M12="","",'Profit and Loss Statement'!M12) -> Crores | ... AI12: =IF('Profit and Loss Statement'!AI12="","",'Profit and Loss Statement'!AI12) -> Crores
E13: AUDITOR_NAME | F13: =IF('Profit and Loss Statement'!F13="","",'Profit and Loss Statement'!F13)
E14: VERSION | F14: =IF('Profit and Loss Statement'!F14="","",'Profit and Loss Statement'!F14)
E15: CIF_ID | F15: =IF('Profit and Loss Statement'!F15="","",'Profit and Loss Statement'!F15)
E16: BASE_YEAR | F16: =IF('Profit and Loss Statement'!F16="","",'Profit and Loss Statement'!F16)
F17: 1 | G17: 2 | H17: 3 | I17: 4 | J17: 5 | K17: 6 | L17: 7 | M17: 8 | N17: 9 | O17: 10 | P17: 11 | Q17: 12 | R17: 13 | S17: 14 | T17: 15 | U17: 16 | V17: 17 | W17: 18 | X17: 19 | Y17: 20 | Z17: 21 | AA17: 22 | AB17: 23 | AC17: 24 | AD17: 25 | AE17: 26 | AF17: 27 | AG17: 28 | AH17: 29 | AI17: 30
A18: UUID | B18: PARENT ID | C18: AUTO_SEQUENCE | D18: INPUT_SEQUENCE | E18: LINE_ITEM_NAME | F18: VALUE | G18: VALUE | H18: VALUE | I18: VALUE | J18: VALUE | K18: VALUE | L18: VALUE | M18: VALUE | N18: VALUE | O18: VALUE | P18: VALUE | Q18: VALUE | R18: VALUE | S18: VALUE | T18: VALUE | U18: VALUE | V18: VALUE | W18: VALUE | X18: VALUE | Y18: VALUE | Z18: VALUE | AA18: VALUE | AB18: VALUE | AC18: VALUE | AD18: VALUE | AE18: VALUE | AF18: VALUE | AG18: VALUE | AH18: VALUE | AI18: VALUE
A19: b2134858-f66e-4654-8e7f-65b9fc91210a | C19: 2 | E19: Balance Sheet
A20: 878de646-becc-492d-a157-3eecec0f591a | B20: b2134858-f66e-4654-8e7f-65b9fc91210a | C20: 2.1 | E20: Balance Sheet (Liabilities)
A21: 06b301db-9d0b-44e9-86a0-a220d1a72804 | B21: 878de646-becc-492d-a157-3eecec0f591a | C21: 2.1.1 | E21: CURRENT LIABILITIES
A22: c6453f22-2f3e-4634-aacb-956d59f1ff9f | B22: 06b301db-9d0b-44e9-86a0-a220d1a72804 | C22: 2.1.1.1 | D22: 1. | E22: Short-term borrowing from banks
A23: eadde075-7734-48ef-9470-b8d214b7937d | B23: c6453f22-2f3e-4634-aacb-956d59f1ff9f | C23: 2.1.1.1.1 | D23: i. | E23: From applicant bank
A24: 0a8ee552-9b62-4de5-a7ca-3826e5d0b2d4 | B24: c6453f22-2f3e-4634-aacb-956d59f1ff9f | C24: 2.1.1.1.2 | D24: ii. | E24: From other banks
A25: afe14fcf-a84e-4d7d-a5cf-7316ce695da4 | B25: c6453f22-2f3e-4634-aacb-956d59f1ff9f | C25: 2.1.1.1.3 | E25: Sub-total [i + ii] (A) | F25: =ROUND(F23+F24,2) -> 0 | G25: =ROUND(G23+G24,2) -> 0 | H25: =ROUND(H23+H24,2) -> 0 | I25: =ROUND(I23+I24,2) -> 0 | J25: =ROUND(J23+J24,2) -> 0 | K25: =ROUND(K23+K24,2) -> 0 | L25: =ROUND(L23+L24,2) -> 0 | M25: =ROUND(M23+M24,2) -> 0 | ... AI25: =ROUND(AI23+AI24,2) -> 0
A26: d6b57745-686a-4ddf-91b2-5c886f8e567a | B26: 06b301db-9d0b-44e9-86a0-a220d1a72804 | C26: 2.1.1.2 | D26: 2.i. | E26: Short term borrowings from others (including mobilization advance)
A27: f9680623-61e8-4e11-9328-3655ee3c1840 | B27: 06b301db-9d0b-44e9-86a0-a220d1a72804 | C27: 2.1.1.3 | D27: ii. | E27: Short term borrowings from Related Parties
A28: 2a445707-4b7f-4173-83b0-14a8e82e561d | B28: 06b301db-9d0b-44e9-86a0-a220d1a72804 | C28: 2.1.1.4 | D28: 3 | E28: Sundry Creditors (Trade)
A29: 801bc503-eff2-4fcd-af1f-8fbd888c91e3 | B29: 06b301db-9d0b-44e9-86a0-a220d1a72804 | C29: 2.1.1.5 | D29: 4 | E29: Advance payments from customers
A30: a2fd7c99-e51a-4e8a-9619-ffea2ed95393 | B30: 06b301db-9d0b-44e9-86a0-a220d1a72804 | C30: 2.1.1.6 | D30: 5 | E30: Provision for taxation
A31: 49b4e462-3a69-4beb-bdd4-49d9f68a147d | B31: 06b301db-9d0b-44e9-86a0-a220d1a72804 | C31: 2.1.1.7 | D31: 6 | E31: Dividend payable
A32: f1ed247e-11bf-41ae-898d-fee1afa02fdb | B32: 06b301db-9d0b-44e9-86a0-a220d1a72804 | C32: 2.1.1.8 | D32: 7 | E32: Other statutory liabilities (due within 1 year)
A33: d70aad0f-962f-4965-a439-72a29570179e | B33: 06b301db-9d0b-44e9-86a0-a220d1a72804 | C33: 2.1.1.9 | D33: 8 | E33: Installments of liabilities due within one year (CPLTD) | F33: =SUM(F$34:F$38) -> 0 | G33: =SUM(G$34:G$38) -> 0 | H33: =SUM(H$34:H$38) -> 0 | I33: =SUM(I$34:I$38) -> 0 | J33: =SUM(J$34:J$38) -> 0 | K33: =SUM(K$34:K$38) -> 0 | L33: =SUM(L$34:L$38) -> 0 | M33: =SUM(M$34:M$38) -> 0 | ... AI33: =SUM(AI$34:AI$38) -> 0
A34: 1398600f-6534-4439-b9f8-62e09e9e4a9b | B34: d70aad0f-962f-4965-a439-72a29570179e | C34: 2.1.1.9.1 | D34: a. | E34: Debentures
A35: c35f7b5e-c85c-4790-8e55-59328184ae50 | B35: d70aad0f-962f-4965-a439-72a29570179e | C35: 2.1.1.9.2 | D35: b. | E35: Preference Shares
A36: b2e9612d-5c39-44fb-866b-a18539f01e4c | B36: d70aad0f-962f-4965-a439-72a29570179e | C36: 2.1.1.9.3 | D36: c. | E36: Rupee Term loans
A37: 92dcf598-a513-414f-ad4f-174cf6291232 | B37: d70aad0f-962f-4965-a439-72a29570179e | C37: 2.1.1.9.4 | D37: d. | E37: Foreign currency loans
A38: aeb0b18d-923d-43c3-a5c8-4477844c9658 | B38: d70aad0f-962f-4965-a439-72a29570179e | C38: 2.1.1.9.5 | D38: e. | E38: Others
A39: ee760a95-6a92-4837-8442-b1904df695f9 | B39: 06b301db-9d0b-44e9-86a0-a220d1a72804 | C39: 2.1.1.10 | D39: 9 | E39: Other current liabilities & provisions | F39: =ROUND(SUM(F$40:F$45),2) -> 0 | G39: =ROUND(SUM(G$40:G$45),2) -> 0 | H39: =ROUND(SUM(H$40:H$45),2) -> 0 | I39: =ROUND(SUM(I$40:I$45),2) -> 0 | J39: =ROUND(SUM(J$40:J$45),2) -> 0 | K39: =ROUND(SUM(K$40:K$45),2) -> 0 | L39: =ROUND(SUM(L$40:L$45),2) -> 0 | M39: =ROUND(SUM(M$40:M$45),2) -> 0 | ... AI39: =ROUND(SUM(AI$40:AI$45),2) -> 0
A40: 99352122-0c01-4f7f-b9bc-4a04097c3cac | B40: ee760a95-6a92-4837-8442-b1904df695f9 | C40: 2.1.1.10.1 | D40: a. | E40: Creditors for Expenses
...

Sheet Additional Information
E1: BORROWER_NAME | F1: =IF('Profit and Loss Statement'!F1="","",'Profit and Loss Statement'!F1)
E2: BORROWER_CODE | F2: =IF('Profit and Loss Statement'!F2="","",'Profit and Loss Statement'!F2)
A3: 4ac3c202-727e-4341-8d5b-85a2bfaa5a5a | E3: TEMPLATE_NAME | F3: Company Financial Template
E4: PROJECT_NAME | F4: =IF('Profit and Loss Statement'!F4="","",'Profit and Loss Statement'!F4)
E5: ACCOUNTING_TYPE | F5: =IF('Profit and Loss Statement'!F5="","",'Profit and Loss Statement'!F5) -> GAAP | G5: =IF('Profit and Loss Statement'!G5="","",'Profit and Loss Statement'!G5) | H5: =IF('Profit and Loss Statement'!H5="","",'Profit and Loss Statement'!H5) | I5: =IF('Profit and Loss Statement'!I5="","",'Profit and Loss Statement'!I5) | J5: =IF('Profit and Loss Statement'!J5="","",'Profit and Loss Statement'!J5) | K5: =IF('Profit and Loss Statement'!K5="","",'Profit and Loss Statement'!K5) | L5: =IF('Profit and Loss Statement'!L5="","",'Profit and Loss Statement'!L5) | M5: =IF('Profit and Loss Statement'!M5="","",'Profit and Loss Statement'!M5) | ... AI5: =IF('Profit and Loss Statement'!AI5="","",'Profit and Loss Statement'!AI5)
E6: FINANCIAL_TYPE | F6: =IF('Profit and Loss Statement'!F6="","",'Profit and Loss Statement'!F6) -> Consolidated | G6: =IF('Profit and Loss Statement'!G6="","",'Profit and Loss Statement'!G6) | H6: =IF('Profit and Loss Statement'!H6="","",'Profit and Loss Statement'!H6) | I6: =IF('Profit and Loss Statement'!I6="","",'Profit and Loss Statement'!I6) | J6: =IF('Profit and Loss Statement'!J6="","",'Profit and Loss Statement'!J6) | K6: =IF('Profit and Loss Statement'!K6="","",'Profit and Loss Statement'!K6) | L6: =IF('Profit and Loss Statement'!L6="","",'Profit and Loss Statement'!L6) | M6: =IF('Profit and Loss Statement'!M6="","",'Profit and Loss Statement'!M6) | ... AI6: =IF('Profit and Loss Statement'!AI6="","",'Profit and Loss Statement'!AI6)
E7: YEAR | F7: =IF('Profit and Loss Statement'!F7="","",'Profit and Loss Statement'!F7) | G7: =IF('Profit and Loss Statement'!G7="","",'Profit and Loss Statement'!G7) | H7: =IF('Profit and Loss Statement'!H7="","",'Profit and Loss Statement'!H7) | I7: =IF('Profit and Loss Statement'!I7="","",'Profit and Loss Statement'!I7) | J7: =IF('Profit and Loss Statement'!J7="","",'Profit and Loss Statement'!J7) | K7: =IF('Profit and Loss Statement'!K7="","",'Profit and Loss Statement'!K7) | L7: =IF('Profit and Loss Statement'!L7="","",'Profit and Loss Statement'!L7) | M7: =IF('Profit and Loss Statement'!M7="","",'Profit and Loss Statement'!M7) | ... AI7: =IF('Profit and Loss Statement'!AI7="","",'Profit and Loss Statement'!AI7)
E8: YEAR_TYPE | F8: =IF('Profit and Loss Statement'!F8="","",'Profit and Loss Statement'!F8) -> Audited | G8: =IF('Profit and Loss Statement'!G8="","",'Profit and Loss Statement'!G8) | H8: =IF('Profit and Loss Statement'!H8="","",'Profit and Loss Statement'!H8) | I8: =IF('Profit and Loss Statement'!I8="","",'Profit and Loss Statement'!I8) | J8: =IF('Profit and Loss Statement'!J8="","",'Profit and Loss Statement'!J8) | K8: =IF('Profit and Loss Statement'!K8="","",'Profit and Loss Statement'!K8) | L8: =IF('Profit and Loss Statement'!L8="","",'Profit and Loss Statement'!L8) | M8: =IF('Profit and Loss Statement'!M8="","",'Profit and Loss Statement'!M8) | ... AI8: =IF('Profit and Loss Statement'!AI8="","",'Profit and Loss Statement'!AI8)
E9: STATEMENT_DATE (YYYY-MM-DD) | F9: =IF('Profit and Loss Statement'!F9="","",'Profit and Loss Statement'!F9) | G9: =IF('Profit and Loss Statement'!G9="","",'Profit and Loss Statement'!G9) | H9: =IF('Profit and Loss Statement'!H9="","",'Profit and Loss Statement'!H9) | I9: =IF('Profit and Loss Statement'!I9="","",'Profit and Loss Statement'!I9) | J9: =IF('Profit and Loss Statement'!J9="","",'Profit and Loss Statement'!J9) | K9: =IF('Profit and Loss Statement'!K9="","",'Profit and Loss Statement'!K9) | L9: =IF('Profit and Loss Statement'!L9="","",'Profit and Loss Statement'!L9) | M9: =IF('Profit and Loss Statement'!M9="","",'Profit and Loss Statement'!M9) | ... AI9: =IF('Profit and Loss Statement'!AI9="","",'Profit and Loss Statement'!AI9)
E10: NO_OF_MONTHS | F10: =IF('Profit and Loss Statement'!F10="","",'Profit and Loss Statement'!F10) | G10: =IF('Profit and Loss Statement'!G10="","",'Profit and Loss Statement'!G10) | H10: =IF('Profit and Loss Statement'!H10="","",'Profit and Loss Statement'!H10) | I10: =IF('Profit and Loss Statement'!I10="","",'Profit and Loss Statement'!I10) | J10: =IF('Profit and Loss Statement'!J10="","",'Profit and Loss Statement'!J10) | K10: =IF('Profit and Loss Statement'!K10="","",'Profit and Loss Statement'!K10) | L10: =IF('Profit and Loss Statement'!L10="","",'Profit and Loss Statement'!L10) | M10: =IF('Profit and Loss Statement'!M10="","",'Profit and Loss Statement'!M10) | ... AI10: =IF('Profit and Loss Statement'!AI10="","",'Profit and Loss Statement'!AI10)
E11: CURRENCY | F11: =IF('Profit and Loss Statement'!F11="","",'Profit and Loss Statement'!F11) -> INR | G11: =IF('Profit and Loss Statement'!G11="","",'Profit and Loss Statement'!G11) -> INR | H11: =IF('Profit and Loss Statement'!H11="","",'Profit and Loss Statement'!H11) -> INR | I11: =IF('Profit and Loss Statement'!I11="","",'Profit and Loss Statement'!I11) -> INR | J11: =IF('Profit and Loss Statement'!J11="","",'Profit and Loss Statement'!J11) -> INR | K11: =IF('Profit and Loss Statement'!K11="","",'Profit and Loss Statement'!K11) -> INR | L11: =IF('Profit and Loss Statement'!L11="","",'Profit and Loss Statement'!L11) -> INR | M11: =IF('Profit and Loss Statement'!M11="","",'Profit and Loss Statement'!M11) -> INR | ... AI11: =IF('Profit and Loss Statement'!AI11="","",'Profit and Loss Statement'!AI11) -> INR
E12: DENOMINATION | F12: =IF('Profit and Loss Statement'!F12="","",'Profit and Loss Statement'!F12) -> Crores | G12: =IF('Profit and Loss Statement'!G12="","",'Profit and Loss Statement'!G12) -> Crores | H12: =IF('Profit and Loss Statement'!H12="","",'Profit and Loss Statement'!H12) -> Crores | I12: =IF('Profit and Loss Statement'!I12="","",'Profit and Loss Statement'!I12) -> Crores | J12: =IF('Profit and Loss Statement'!J12="","",'Profit and Loss Statement'!J12) -> Crores | K12: =IF('Profit and Loss Statement'!K12="","",'Profit and Loss Statement'!K12) -> Crores | L12: =IF('Profit and Loss Statement'!L12="","",'Profit and Loss Statement'!L12) -> Crores | M12: =IF('Profit and Loss Statement'!M12="","",'Profit and Loss Statement'!M12) -> Crores | ... AI12: =IF('Profit and Loss Statement'!AI12="","",'Profit and Loss Statement'!AI12) -> Crores
E13: AUDITOR_NAME | F13: =IF('Profit and Loss Statement'!F13="","",'Profit and Loss Statement'!F13)
E14: VERSION | F14: =IF('Profit and Loss Statement'!F14="","",'Profit and Loss Statement'!F14)
E15: CIF_ID | F15: =IF('Profit and Loss Statement'!F15="","",'Profit and Loss Statement'!F15)
E16: BASE_YEAR | F16: =IF('Profit and Loss Statement'!F16="","",'Profit and Loss Statement'!F16)
F17: 1 | G17: 2 | H17: 3 | I17: 4 | J17: 5 | K17: 6 | L17: 7 | M17: 8 | N17: 9 | O17: 10 | P17: 11 | Q17: 12 | R17: 13 | S17: 14 | T17: 15 | U17: 16 | V17: 17 | W17: 18 | X17: 19 | Y17: 20 | Z17: 21 | AA17: 22 | AB17: 23 | AC17: 24 | AD17: 25 | AE17: 26 | AF17: 27 | AG17: 28 | AH17: 29 | AI17: 30
A18: UUID | B18: PARENT ID | C18: AUTO_SEQUENCE | D18: INPUT_SEQUENCE | E18: LINE_ITEM_NAME | F18: VALUE | G18: VALUE | H18: VALUE | I18: VALUE | J18: VALUE | K18: VALUE | L18: VALUE | M18: VALUE | N18: VALUE | O18: VALUE | P18: VALUE | Q18: VALUE | R18: VALUE | S18: VALUE | T18: VALUE | U18: VALUE | V18: VALUE | W18: VALUE | X18: VALUE | Y18: VALUE | Z18: VALUE | AA18: VALUE | AB18: VALUE | AC18: VALUE | AD18: VALUE | AE18: VALUE | AF18: VALUE | AG18: VALUE | AH18: VALUE | AI18: VALUE
A19: 0dba63d6-0776-413f-8351-2f2222c3cb3f | C19: 3 | E19: Additional Information
A20: b819a9c0-df6d-41e8-a77f-2e13875e4712 | B20: 0dba63d6-0776-413f-8351-2f2222c3cb3f | C20: 3.1 | D20: A. | E20: Contingent Liabilities: | F20: =SUM(F21:F30) -> 0 | G20: =SUM(G21:G30) -> 0 | H20: =SUM(H21:H30) -> 0 | I20: =SUM(I21:I30) -> 0 | J20: =SUM(J21:J30) -> 0 | K20: =SUM(K21:K30) -> 0 | L20: =SUM(L21:L30) -> 0 | M20: =SUM(M21:M30) -> 0 | ... AI20: =SUM(AI21:AI30) -> 0
A21: d721df33-74ba-4cc6-85ef-abefa98e5b85 | B21: b819a9c0-df6d-41e8-a77f-2e13875e4712 | C21: 3.1.1 | D21: a.i. | E21: Arrears of Cumulative Dividends
A22: 608921b7-1017-40be-9ac7-b0842e96b22d | B22: b819a9c0-df6d-41e8-a77f-2e13875e4712 | C22: 3.1.2 | D22: ii | E22: Gratuity Liability Not Provided For
A23: 66d2dbbe-de69-408e-9f7f-de4962c2c0e6 | B23: b819a9c0-df6d-41e8-a77f-2e13875e4712 | C23: 3.1.3 | D23: iii | E23: Disputed Excise / Customs / Tax Liabilities
A24: 9415d0bd-e759-4de8-bc98-4912a316ff90 | B24: b819a9c0-df6d-41e8-a77f-2e13875e4712 | C24: 3.1.4 | D24: iv. | E24: Other liabilities not provided for
A25: afc4b84c-c2b7-40c5-8e27-1640b795df46 | B25: b819a9c0-df6d-41e8-a77f-2e13875e4712 | C25: 3.1.5 | D25: b.i. | E25: Outstanding LCs
A26: f66e3fe5-a767-415b-b422-8bd5172f99ba | B26: b819a9c0-df6d-41e8-a77f-2e13875e4712 | C26: 3.1.6 | D26: ii. | E26: Outstanding bills discounted & purchased
A27: 7c3df7a3-c623-4e07-8aa0-9bb150d158c0 | B27: b819a9c0-df6d-41e8-a77f-2e13875e4712 | C27: 3.1.7 | D27: iii. | E27: Outstanding BGs
A28: 1ccd391d-bec6-4510-b53a-54be4cd981bc | B28: b819a9c0-df6d-41e8-a77f-2e13875e4712 | C28: 3.1.8 | D28: c. | E28: Financial Guarantees issued by the company
A29: 7b9f63a7-81df-4936-843d-b562ab36499b | B29: b819a9c0-df6d-41e8-a77f-2e13875e4712 | C29: 3.1.9 | D29: d.i. | E29: Redemption premium not provided for
A30: 52f8c582-10f5-4d7b-9dae-05c0c9cb0195 | B30: b819a9c0-df6d-41e8-a77f-2e13875e4712 | C30: 3.1.10 | D30: ii. | E30: MTM loss on derivatives not provided for
A31: 56367121-7aaf-430d-8353-418a911ca699 | B31: 0dba63d6-0776-413f-8351-2f2222c3cb3f | C31: 3.2 | D31: B | E31: Crystallized losses in the year without routing through P&L account
A32: d81c68ed-0f4e-4e71-883f-560fe7f22bd9 | B32: 0dba63d6-0776-413f-8351-2f2222c3cb3f | C32: 3.3 | D32: C | E32: Accumulated depreciation on fixed assets sold/ discarded during the year
A33: 4749684c-2a79-479c-8ef0-d6f7f8ec7252 | B33: 0dba63d6-0776-413f-8351-2f2222c3cb3f | C33: 3.4 | D33: D | E33: Accumulated amortization on intangible assets sold/ discarded during the year
A34: b2eff56f-bbd6-4b5a-8510-05851535a1ba | B34: 0dba63d6-0776-413f-8351-2f2222c3cb3f | C34: 3.5 | D34: E | E34: Write-off in value of stock in process during the year | F34: ='Profit and Loss Statement'!F77 -> 0 | G34: ='Profit and Loss Statement'!G77 -> 0 | H34: ='Profit and Loss Statement'!H77 -> 0 | I34: ='Profit and Loss Statement'!I77 -> 0 | J34: ='Profit and Loss Statement'!J77 -> 0 | K34: ='Profit and Loss Statement'!K77 -> 0 | L34: ='Profit and Loss Statement'!L77 -> 0 | M34: ='Profit and Loss Statement'!M77 -> 0 | ... AI34: ='Profit and Loss Statement'!AI77 -> 0
A35: 825f0ef2-92f1-491a-826d-e2645481f1f2 | B35: 0dba63d6-0776-413f-8351-2f2222c3cb3f | C35: 3.6 | D35: F | E35: Write-off in value of finished goods during the year | F35: ='Profit and Loss Statement'!F78 -> 0 | G35: ='Profit and Loss Statement'!G78 -> 0 | H35: ='Profit and Loss Statement'!H78 -> 0 | I35: ='Profit and Loss Statement'!I78 -> 0 | J35: ='Profit and Loss Statement'!J78 -> 0 | K35: ='Profit and Loss Statement'!K78 -> 0 | L35: ='Profit and Loss Statement'!L78 -> 0 | M35: ='Profit and Loss Statement'!M78 -> 0 | ... AI35: ='Profit and Loss Statement'!AI78 -> 0

Sheet Ratios
E1: BORROWER_NAME
E2: BORROWER_CODE
A3: 988a49f2-7288-402f-99fc-87d1bf295447 | E3: TEMPLATE_NAME | F3: Company Financial Template
E4: PROJECT_NAME
E5: ACCOUNTING_TYPE
E6: FINANCIAL_TYPE
E7: YEAR
E8: YEAR_TYPE
E9: STATEMENT_DATE (YYYY-MM-DD)
E10: NO_OF_MONTHS
E11: CURRENCY
E12: DENOMINATION
E13: AUDITOR_NAME
E14: VERSION
E15: CIF_ID
E16: BASE_YEAR
F17: 1 | G17: 2 | H17: 3 | I17: 4 | J17: 5 | K17: 6 | L17: 7 | M17: 8 | N17: 9 | O17: 10 | P17: 11 | Q17: 12 | R17: 13 | S17: 14 | T17: 15 | U17: 16 | V17: 17 | W17: 18 | X17: 19 | Y17: 20 | Z17: 21 | AA17: 22 | AB17: 23 | AC17: 24 | AD17: 25 | AE17: 26 | AF17: 27 | AG17: 28 | AH17: 29 | AI17: 30
A18: UUID | B18: PARENT ID | C18: AUTO_SEQUENCE | D18: INPUT_SEQUENCE | E18: LINE_ITEM_NAME | F18: VALUE | G18: VALUE | H18: VALUE | I18: VALUE | J18: VALUE | K18: VALUE | L18: VALUE | M18: VALUE | N18: VALUE | O18: VALUE | P18: VALUE | Q18: VALUE | R18: VALUE | S18: VALUE | T18: VALUE | U18: VALUE | V18: VALUE | W18: VALUE | X18: VALUE | Y18: VALUE | Z18: VALUE | AA18: VALUE | AB18: VALUE | AC18: VALUE | AD18: VALUE | AE18: VALUE | AF18: VALUE | AG18: VALUE | AH18: VALUE | AI18: VALUE
A19: b8cf3817-536a-4500-a4a3-4d86a0a3f882 | C19: 4 | E19: Ratios
A20: 74fad8f6-8858-42dc-9dda-b4bfacb8c644 | B20: b8cf3817-536a-4500-a4a3-4d86a0a3f882 | C20: 4.1 | D20: 1 | E20: TOI
A21: 4b8ffc50-6a9b-4794-a768-490d48542485 | B21: b8cf3817-536a-4500-a4a3-4d86a0a3f882 | C21: 4.2 | D21: 2 | E21: EBIDTA
A22: 6482e5f1-6164-4430-b6e3-6578bd299e76 | B22: b8cf3817-536a-4500-a4a3-4d86a0a3f882 | C22: 4.3 | D22: 3 | E22: EBIDTA/TOI (%)
A23: dbfeabc7-6fdb-4a4a-8d8c-19b7c24afa0f | B23: b8cf3817-536a-4500-a4a3-4d86a0a3f882 | C23: 4.4 | D23: 4 | E23: Interest
A24: 8d3f273c-0938-4a47-8c87-d2da79190214 | B24: b8cf3817-536a-4500-a4a3-4d86a0a3f882 | C24: 4.5 | D24: 5 | E24: Depreciation and Amortization
A25: 51d37c1c-a3f7-44c9-bd94-6bf1a38ba12f | B25: b8cf3817-536a-4500-a4a3-4d86a0a3f882 | C25: 4.6 | D25: 6 | E25: Operating profit
A26: 77453387-fb2f-4e9a-820c-dca234ce0d7c | B26: b8cf3817-536a-4500-a4a3-4d86a0a3f882 | C26: 4.7 | D26: 7 | E26: Net non-operating income
A27: df6073c0-5418-4909-b0b3-cdb37fa69927 | B27: b8cf3817-536a-4500-a4a3-4d86a0a3f882 | C27: 4.8 | D27: 8 | E27: PBT
A28: 1584e341-e6c2-411b-aa12-b5dd6613092c | B28: b8cf3817-536a-4500-a4a3-4d86a0a3f882 | C28: 4.9 | D28: 9 | E28: PAT
A29: c199b620-e552-49e1-a9d0-3c468413c690 | B29: b8cf3817-536a-4500-a4a3-4d86a0a3f882 | C29: 4.10 | D29: 10 | E29: PAT/TOI (%)
A30: 08efe169-580d-4daa-9b58-477ade83248b | B30: b8cf3817-536a-4500-a4a3-4d86a0a3f882 | C30: 4.11 | D30: 11 | E30: NCA
A31: 6a44f956-ba1d-4799-93e6-249efeb3e389 | B31: b8cf3817-536a-4500-a4a3-4d86a0a3f882 | C31: 4.12 | D31: 12 | E31: NFA
... A34: 28c4d392-680e-43f6-856d-e7a7beb453ef | B34: b8cf3817-536a-4500-a4a3-4d86a0a3f882 | C34: 4.15 | D34: 15 | E34: Exposure in subsidiaries/Group Cos.
A35: 14cff825-5a85-4e12-8534-8d07d7039113 | B35: 28c4d392-680e-43f6-856d-e7a7beb453ef | C35: 4.15.1 | E35: Investments
A36: f68509c3-70d2-43ff-a3d4-04c467770664 | B36: 28c4d392-680e-43f6-856d-e7a7beb453ef | C36: 4.15.2 | E36: Loans and advances
A37: 0469177e-752b-49a0-9837-fb5dd1980098 | B37: b8cf3817-536a-4500-a4a3-4d86a0a3f882 | C37: 4.16 | D37: 16 | E37: Adjusted TNW (ATNW)
A38: e8f0fe7c-d8bc-4d04-b962-bd923918c71f | B38: b8cf3817-536a-4500-a4a3-4d86a0a3f882 | C38: 4.17 | D38: 17 | E38: Long term debt (LTD) (A)
A39: ece6234d-d6b2-4e97-8691-1ed4f1c5f56d | B39: b8cf3817-536a-4500-a4a3-4d86a0a3f882 | C39: 4.18 | D39: 18 | E39: Short term debt (STD) (B)
A40: ca6dcd17-f145-488b-a14d-973d169a64b5 | B40: b8cf3817-536a-4500-a4a3-4d86a0a3f882 | C40: 4.19 | E40: Term loan repayments
A41: 2b40911d-cd89-4fe7-9004-fe983994154d | B41: b8cf3817-536a-4500-a4a3-4d86a0a3f882 | C41: 4.20 | E41: Other working capital STD
A42: 8f9dfa3f-0033-49a6-8050-f14917dc09a5 | B42: b8cf3817-536a-4500-a4a3-4d86a0a3f882 | C42: 4.21 | D42: 19 | E42: WC bank finance (C)
...

Sheet Financial Spreading & Analysis
A1: v | E1: BORROWER_NAME
E2: BORROWER_CODE
E3: TEMPLATE_NAME | F3: Company Financial Template
E4: PROJECT_NAME
E5: ACCOUNTING_TYPE
E6: FINANCIAL_TYPE
E7: YEAR
E8: YEAR_TYPE
E9: STATEMENT_DATE (YYYY-MM-DD)
E10: NO_OF_MONTHS
E11: CURRENCY
E12: DENOMINATION
E13: AUDITOR_NAME
E14: VERSION
E15: CIF_ID
E16: BASE_YEAR
D17: BASE_YEAR | F17: -30 | G17: -29 | H17: -28 | I17: -27 | J17: -26 | K17: -25 | L17: -24 | M17: -23 | N17: -22 | O17: -21 | P17: -20 | Q17: -19 | R17: -18 | S17: -17 | T17: -16 | U17: -15 | V17: -14 | W17: -13 | X17: -12 | Y17: -11 | Z17: -10 | AA17: -9 | AB17: -8 | AC17: -7 | AD17: -6 | AE17: -5 | AF17: -4 | AG17: -3 | AH17: -2 | AI17: -1 | AJ17: 0 | AK17: 1 | AL17: 2 | AM17: 3 | AN17: 4 | AO17: 5 | AP17: 6 | AQ17: 7 | AR17: 8 | AS17: 9 | AT17: 10 | AU17: 11 | AV17: 12 | AW17: 13 | AX17: 14 | AY17: 15 | AZ17: 16 | BA17: 17 | BB17: 18 | BC17: 19 | BD17: 20 | BE17: 21 | BF17: 22 | BG17: 23 | BH17: 24 | BI17: 25 | BJ17: 26 | BK17: 27 | BL17: 28 | BM17: 29 | BN17: 30 | BO17: Projection Method Name | BP17: 1 | BQ17: 2 | BR17: 3 | BS17: 4 | BT17: 5 | BU17: 6 | BV17: 7 | BW17: 8 | BX17: 9 | BY17: 10 | BZ17: 11 | CA17: 12 | CB17: 13 | CC17: 14 | CD17: 15 | CE17: Projection Method Name | CF17: 1 | CG17: 2 | CH17: 3 | CI17: 4 | CJ17: 5 | CK17: 6 | CL17: 7 | CM17: 8 | CN17: 9 | CO17: 10 | CP17: 11 | CQ17: 12 | CR17: 13 | CS17: 14 | CT17: 15 | CU17: Projection Method Name | CV17: 1 | CW17: 2 | CX17: 3 | CY17: 4 | CZ17: 5 | DA17: 6 | DB17: 7 | DC17: 8 | DD17: 9 | DE17: 10 | DF17: 11 | DG17: 12 | DH17: 13 | DI17: 14 | DJ17: 15 | DK17: Projection Method Name | DL17: 1 | DM17: 2 | DN17: 3 | DO17: 4 | DP17: 5 | DQ17: 6 | DR17: 7 | DS17: 8 | DT17: 9 | DU17: 10 | DV17: 11 | DW17: 12 | DX17: 13 | DY17: 14 | DZ17: 15 | EA17: Projection Method Name | EB17: 1 | EC17: 2 | ED17: 3 | EE17: 4 | EF17: 5 | EG17: 6 | EH17: 7 | EI17: 8 | EJ17: 9 | EK17: 10 | EL17: 11 | EM17: 12 | EN17: 13 | EO17: 14 | EP17: 15
D18: Rating Year | E18: 2026 | BO18: MINIMUM | CE18: MAXIMUM | CU18: AVERAGE | DK18: REGRESSION | EA18: ADHOC
A20: UUID | B20: PARENT ID | C20: AUTO_SEQUENCE | D20: INPUT_SEQUENCE | E20: LINE_ITEM_NAME | F20: =SUM(E17,F17) -> -30 | G20: =SUM(E17,G17) -> -29 | H20: =SUM(E17,H17) -> -28 | I20: =SUM(E17,I17) -> -27 | J20: =SUM(E17,J17) -> -26 | K20: =SUM(E17,K17) -> -25 | L20: =SUM(E17,L17) -> -24 | M20: =SUM(E17,M17) -> -23 | N20: =SUM(E17,N17) -> -22 | O20: =SUM(E17,O17) -> -21 | P20: =SUM(E17,P17) -> -20 | Q20: =SUM(E17,Q17) -> -19 | R20: =SUM(E17,R17) -> -18 | S20: =SUM(E17,S17) -> -17 | T20: =SUM(E17,T17) -> -16 | U20: =SUM(E17,U17) -> -15 | V20: =SUM(E17,V17) -> -14 | W20: =SUM(E17,W17) -> -13 | X20: =SUM(E17,X17) -> -12 | Y20: =SUM(E17,Y17) -> -11 | Z20: =SUM(E17,Z17) -> -10 | AA20: =SUM(E17,AA17) -> -9 | AB20: =SUM(E17,AB17) -> -8 | AC20: =SUM(E17,AC17) -> -7 | AD20: =SUM(E17,AD17) -> -6 | AE20: =SUM(E17,AE17) -> -5 | AF20: =SUM(E17,AF17) -> -4 | AG20: =SUM(E17,AG17) -> -3 | AH20: =SUM(E17,AH17) -> -2 | AI20: =SUM(E17,AI17) -> -1 | AJ20: =SUM(E17,AJ17) -> 0 | AK20: =SUM(E17,AK17) -> 1 | AL20: =SUM(E17,AL17) -> 2 | AM20: =SUM(E17,AM17) -> 3 | AN20: =SUM(E17,AN17) -> 4 | AO20: =SUM(E17,AO17) -> 5 | AP20: =SUM(E17,AP17) -> 6 | AQ20: =SUM(E17,AQ17) -> 7 | AR20: =SUM(E17,AR17) -> 8 | AS20: =SUM(E17,AS17) -> 9 | AT20: =SUM(E17,AT17) -> 10 | AU20: =SUM(E17,AU17) -> 11 | AV20: =SUM(E17,AV17) -> 12 | AW20: =SUM(E17,AW17) -> 13 | AX20: =SUM(E17,AX17) -> 14 | AY20: =SUM(E17,AY17) -> 15 | AZ20: =SUM(E17,AZ17) -> 16 | BA20: =SUM(E17,BA17) -> 17 | BB20: =SUM(E17,BB17) -> 18 | BC20: =SUM(E17,BC17) -> 19 | BD20: =SUM(E17,BD17) -> 20 | BE20: =SUM(E17,BE17) -> 21 | BF20: =SUM(E17,BF17) -> 22 | BG20: =SUM(E17,BG17) -> 23 | BH20: =SUM(E17,BH17) -> 24 | BI20: =SUM(E17,BI17) -> 25 | BJ20: =SUM(E17,BJ17) -> 26 | BK20: =SUM(E17,BK17) -> 27 | BL20: =SUM(E17,BL17) -> 28 | BM20: =SUM(E17,BM17) -> 29 | BN20: =SUM(E17,BN17) -> 30 | BP20: =SUM(E17,BP17) -> 1 | BQ20: =SUM(E17,BQ17) -> 2 | BR20: =SUM(E17,BR17) -> 3 | BS20: =SUM(E17,BS17) -> 4 | BT20: =SUM(E17,BT17) -> 5 | BU20: =SUM(E17,BU17) -> 6 | BV20: =SUM(E17,BV17) -> 7 | BW20: =SUM(E17,BW17) -> 8 | BX20: =SUM(E17,BX17) -> 9 | BY20: =SUM(E17,BY17) -> 10 | BZ20: =SUM(E17,BZ17) -> 11 | CA20: =SUM(E17,CA17) -> 12 | CB20: =SUM(E17,CB17) -> 13 | CC20: =SUM(E17,CC17) -> 14 | CD20: =SUM(E17,CD17) -> 15 | CF20: =SUM(E17,CF17) -> 1 | CG20: =SUM(E17,CG17) -> 2 | CH20: =SUM(E17,CH17) -> 3 | CI20: =SUM(E17,CI17) -> 4 | CJ20: =SUM(E17,CJ17) -> 5 | CK20: =SUM(E17,CK17) -> 6 | CL20: =SUM(E17,CL17) -> 7 | CM20: =SUM(E17,CM17) -> 8 | CN20: =SUM(E17,CN17) -> 9 | CO20: =SUM(E17,CO17) -> 10 | CP20: =SUM(E17,CP17) -> 11 | CQ20: =SUM(E17,CQ17) -> 12 | CR20: =SUM(E17,CR17) -> 13 | CS20: =SUM(E17,CS17) -> 14 | CT20: =SUM(E17,CT17) -> 15 | CV20: =SUM(E17,CV17) -> 1 | CW20: =SUM(E17,CW17) -> 2 | CX20: =SUM(E17,CX17) -> 3 | CY20: =SUM(E17,CY17) -> 4 | CZ20: =SUM(E17,CZ17) -> 5 | DA20: =SUM(E17,DA17) -> 6 | DB20: =SUM(E17,DB17) -> 7 | DC20: =SUM(E17,DC17) -> 8 | DD20: =SUM(E17,DD17) -> 9 | DE20: =SUM(E17,DE17) -> 10 | DF20: =SUM(E17,DF17) -> 11 | DG20: =SUM(E17,DG17) -> 12 | DH20: =SUM(E17,DH17) -> 13 | DI20: =SUM(E17,DI17) -> 14 | DJ20: =SUM(E17,DJ17) -> 15 | DL20: =SUM(E17,DL17) -> 1 | DM20: =SUM(E17,DM17) -> 2 | DN20: =SUM(E17,DN17) -> 3 | DO20: =SUM(E17,DO17) -> 4 | DP20: =SUM(E17,DP17) -> 5 | DQ20: =SUM(E17,DQ17) -> 6 | DR20: =SUM(E17,DR17) -> 7 | DS20: =SUM(E17,DS17) -> 8 | DT20: =SUM(E17,DT17) -> 9 | DU20: =SUM(E17,DU17) -> 10 | DV20: =SUM(E17,DV17) -> 11 | DW20: =SUM(E17,DW17) -> 12 | DX20: =SUM(E17,DX17) -> 13 | DY20: =SUM(E17,DY17) -> 14 | DZ20: =SUM(E17,DZ17) -> 15 | EB20: =SUM(E17,EB17) -> 1 | EC20: =SUM(E17,EC17) -> 2 | ED20: =SUM(E17,ED17) -> 3 | EE20: =SUM(E17,EE17) -> 4 | EF20: =SUM(E17,EF17) -> 5 | EG20: =SUM(E17,EG17) -> 6 | EH20: =SUM(E17,EH17) -> 7 | EI20: =SUM(E17,EI17) -> 8 | EJ20: =SUM(E17,EJ17) -> 9 | EK20: =SUM(E17,EK17) -> 10 | EL20: =SUM(E17,EL17) -> 11 | EM20: =SUM(E17,EM17) -> 12 | EN20: =SUM(E17,EN17) -> 13 | EO20: =SUM(E17,EO17) -> 14 | EP20: =SUM(E17,EP17) -> 15
A21: c98dd930-c06b-4184-a258-ac39cd19a193 | C21: 1 | E21: Profit and Loss Statement
A22: 10a60949-9659-4ea4-b1c3-1f16074a2874 | B22: c98dd930-c06b-4184-a258-ac39cd19a193 | C22: 1.1 | D22: 1 | E22: Gross Sales
A23: 1fe0fddb-2578-4028-bb64-bd63d70cdd09 | B23: 10a60949-9659-4ea4-b1c3-1f16074a2874 | C23: 1.1.1 | D23: 1.1 | E23: Domestic Sales
A24: 725d10e1-e2a6-4996-b9d0-4ad6ffc75b68 | B24: 10a60949-9659-4ea4-b1c3-1f16074a2874 | C24: 1.1.2 | D24: 1.2 | E24: Export Sales
A25: 640dbfc9-deeb-44e3-9198-96949e0cae58 | B25: 10a60949-9659-4ea4-b1c3-1f16074a2874 | C25: 1.1.3 | D25: 1.3 | E25: Total | F25: =ROUND(SUM(F$23:F$24),2) -> 0 | G25: =ROUND(SUM(G$23:G$24),2) -> 0 | H25: =ROUND(SUM(H$23:H$24),2) -> 0 | I25: =ROUND(SUM(I$23:I$24),2) -> 0 | J25: =ROUND(SUM(J$23:J$24),2) -> 0 | K25: =ROUND(SUM(K$23:K$24),2) -> 0 | L25: =ROUND(SUM(L$23:L$24),2) -> 0 | M25: =ROUND(SUM(M$23:M$24),2) -> 0 | ... BN25: =ROUND(SUM(BN$23:BN$24),2) -> 0
A26: 59b1facc-2b05-4ef0-bd3c-52d6156b19af | B26: c98dd930-c06b-4184-a258-ac39cd19a193 | C26: 1.2 | D26: 2 | E26: Less Excise Duty
A27: a3c6e8f3-99c4-41a0-adec-acb5ff2f3b00 | B27: c98dd930-c06b-4184-a258-ac39cd19a193 | C27: 1.3 | D27: 3 | E27: Net Sales (1 - 2) | F27: =ROUND(F25-F26,2) -> 0 | G27: =ROUND(G25-G26,2) -> 0 | H27: =ROUND(H25-H26,2) -> 0 | I27: =ROUND(I25-I26,2) -> 0 | J27: =ROUND(J25-J26,2) -> 0 | K27: =ROUND(K25-K26,2) -> 0 | L27: =ROUND(L25-L26,2) -> 0 | M27: =ROUND(M25-M26,2) -> 0 | ... BN27: =ROUND(BN25-BN26,2) -> 0
A28: 48b561dd-2f32-4bf9-9890-f458e178e892 | B28: c98dd930-c06b-4184-a258-ac39cd19a193 | C28: 1.4 | E28: % age rise (+) or fall (-) in net sales as compared to previous year (annualised) | G28: =IF(F27=0,0,IF(G27=0,0,((G27/G10)-(F27/F10))/(F27/F10))*100) -> 0 | H28: =IF(G27=0,0,IF(H27=0,0,((H27/H10)-(G27/G10))/(G27/G10))*100) -> 0 | I28: =IF(H27=0,0,IF(I27=0,0,((I27/I10)-(H27/H10))/(H27/H10))*100) -> 0 | J28: =IF(I27=0,0,IF(J27=0,0,((J27/J10)-(I27/I10))/(I27/I10))*100) -> 0 | K28: =IF(J27=0,0,IF(K27=0,0,((K27/K10)-(J27/J10))/(J27/J10))*100) -> 0 | L28: =IF(K27=0,0,IF(L27=0,0,((L27/L10)-(K27/K10))/(K27/K10))*100) -> 0 | M28: =IF(L27=0,0,IF(M27=0,0,((M27/M10)-(L27/L10))/(L27/L10))*100) -> 0 | N28: =IF(M27=0,0,IF(N27=0,0,((N27/N10)-(M27/M10))/(M27/M10))*100) -> 0 | ... BN28: =IF(BM27=0,0,IF(BN27=0,0,((BN27/BN10)-(BM27/BM10))/(BM27/BM10))*100) -> 0
A29: 16c1b0ac-ba37-4ed6-bb75-c0d4993e9ae8 | B29: c98dd930-c06b-4184-a258-ac39cd19a193 | C29: 1.5 | E29: Other recurring income incidental to main business
A30: 758d688a-abd2-4efa-bace-54c0f837efaa | B30: c98dd930-c06b-4184-a258-ac39cd19a193 | C30: 1.6 | D30: 4 | E30: Total operating income | F30: =F27+F29 -> 0 | G30: =G27+G29 -> 0 | H30: =H27+H29 -> 0 | I30: =I27+I29 -> 0 | J30: =J27+J29 -> 0 | K30: =K27+K29 -> 0 | L30: =L27+L29 -> 0 | M30: =M27+M29 -> 0 | ... BN30: =BN27+BN29 -> 0
A31: 03e7d409-963e-4698-9508-323cb4718bd7 | B31: c98dd930-c06b-4184-a258-ac39cd19a193 | C31: 1.7 | D31: 5 | E31: Cost of Sales
A32: 3d4377af-5b9d-4fc5-8ad3-56f2be931ed3 | B32: 03e7d409-963e-4698-9508-323cb4718bd7 | C32: 1.7.1 | D32: i. | E32: Raw materials | F32: =ROUND(SUM(F$33:F$34),2) -> 0 | G32: =ROUND(SUM(G$33:G$34),2) -> 0 | H32: =ROUND(SUM(H$33:H$34),2) -> 0 | I32: =ROUND(SUM(I$33:I$34),2) -> 0 | J32: =ROUND(SUM(J$33:J$34),2) -> 0 | K32: =ROUND(SUM(K$33:K$34),2) -> 0 | L32: =ROUND(SUM(L$33:L$34),2) -> 0 | M32: =ROUND(SUM(M$33:M$34),2) -> 0 | ... BN32: =ROUND(SUM(BN$33:BN$34),2) -> 0
A33: d4fd265c-aebb-4d35-8d34-fbb90f8879b1 | B33: 3d4377af-5b9d-4fc5-8ad3-56f2be931ed3 | C33: 1.7.1.1 | D33: a. | E33: i) Imported
A34: 196afb1b-3271-4e26-8c17-a1687f1442a1 | B34: 3d4377af-5b9d-4fc5-8ad3-56f2be931ed3 | C34: 1.7.1.2 | D34: b. | E34: ii) Indigenous
A35: b5374b98-fbc9-4afd-91a6-687949a4353a | B35: 03e7d409-963e-4698-9508-323cb4718bd7 | C35: 1.7.2 | D35: ii. | E35: Other Spares
A36: f78f861b-e42f-4c79-b4df-5106e411ae92 | B36: 03e7d409-963e-4698-9508-323cb4718bd7 | C36: 1.7.3 | D36: iii. | E36: Power and Fuel
A37: 148302c9-c702-4281-9fb6-424bb1a09513 | B37: 03e7d409-963e-4698-9508-323cb4718bd7 | C37: 1.7.4 | D37: iv. | E37: Direct Labour (Factory wages & salaries)
A38: a8cd1b47-c726-4920-a36e-c957dd5e4e35 | B38: 03e7d409-963e-4698-9508-323cb4718bd7 | C38: 1.7.5 | D38: v. | E38: Other manufacturing expenses | F38: =ROUND(SUM(F$39:F$41),2) -> 0 | G38: =ROUND(SUM(G$39:G$41),2) -> 0 | H38: =ROUND(SUM(H$39:H$41),2) -> 0 | I38: =ROUND(SUM(I$39:I$41),2) -> 0 | J38: =ROUND(SUM(J$39:J$41),2) -> 0 | K38: =ROUND(SUM(K$39:K$41),2) -> 0 | L38: =ROUND(SUM(L$39:L$41),2) -> 0 | M38: =ROUND(SUM(M$39:M$41),2) -> 0 | ... BN38: =ROUND(SUM(BN$39:BN$41),2) -> 0
A39: 668ded41-a4aa-46a3-9c6a-800d00837629 | B39: a8cd1b47-c726-4920-a36e-c957dd5e4e35 | C39: 1.7.5.1 | D39: a. | E39: Processing / Job Work Charges
A40: 0ad52017-0aff-4518-ab1c-4f3090d51d34 | B40: a8cd1b47-c726-4920-a36e-c957dd5e4e35 | C40: 1.7.5.2 | D40: b. | E40: Freight and Transportation Charges
A41: 4920a1ca-7f77-41b8-b737-00b8b1672a4b | B41: a8cd1b47-c726-4920-a36e-c957dd5e4e35 | C41: 1.7.5.3 | D41: c. | E41: Others
...
